#VRML_SIM R2023a utf8

EXTERNPROTO "https://raw.githubusercontent.com/cyberbotics/webots/R2023a/projects/objects/backgrounds/protos/TexturedBackground.proto"
EXTERNPROTO "https://raw.githubusercontent.com/cyberbotics/webots/R2023a/projects/objects/backgrounds/protos/TexturedBackgroundLight.proto"
EXTERNPROTO "https://raw.githubusercontent.com/cyberbotics/webots/R2023a/projects/objects/floors/protos/CircleArena.proto"

WorldInfo {
}
Viewpoint {
  orientation -0.18962677464485928 -0.06948791607320202 0.9793942596613436 3.8307463527986108
  position 0.8319947592482319 0.7599065516840124 0.31817863111228534
}
TexturedBackground {
}
TexturedBackgroundLight {
}
DirectionalLight {
  direction 0 -1 0
}
CircleArena {
}
Robot {
  translation 6.528389887882725e-10 -2.612784273940576e-06 -0.0002199975451767644
  rotation 0.857810989702284 0.5139652769062045 -8.98422743694486e-06 9.170715887999672e-06
  children [
    DistanceSensor {
      translation 0.042 -0.02 0.063
      rotation 0 -1 0 -0.0004053071795864227
      children [
        DEF SENSOR Transform {
          rotation 0 1 0 1.57
          children [
            Shape {
              appearance PBRAppearance {
                baseColor 1 1 0
                roughness 1
                metalness 0
              }
              geometry Cylinder {
                height 0.004
                radius 0.008
              }
            }
          ]
        }
      ]
      name "ds1"
      lookupTable [
        0 1020 0
        0.05 1020 0
        0.15 0 0
      ]
      numberOfRays 2
      aperture 1
    }
    DistanceSensor {
      translation 0.042 0.02 0.063
      rotation 0 -1 0 -0.0004053071795864227
      children [
        DEF SENSOR Transform {
          rotation 0 1 0 1.57
          children [
            Shape {
              appearance PBRAppearance {
                baseColor 1 1 0
                roughness 1
                metalness 0
              }
              geometry Cylinder {
                height 0.004
                radius 0.008
              }
            }
          ]
        }
      ]
      name "ds0"
      lookupTable [
        0 1020 0
        0.05 1020 0
        0.15 0 0
      ]
      numberOfRays 2
      aperture 1
    }
    HingeJoint {
      jointParameters HingeJointParameters {
        position 1.8172838642195473e-07
        axis 0 1 0
        anchor 0 0 0.025
      }
      device [
        RotationalMotor {
          name "left wheel motor"
        }
      ]
      endPoint Solid {
        translation 0 0.045 0.025
        rotation 0 1 0 1.812804499357409e-07
        children [
          DEF WHEEL Transform {
            rotation 1 0 0 1.57
            children [
              Shape {
                appearance PBRAppearance {
                  baseColor 1 0 0
                  roughness 1
                  metalness 0
                }
                geometry Cylinder {
                  height 0.01
                  radius 0.025
                }
              }
            ]
          }
        ]
        name "LEFT WHEEL"
        boundingObject USE WHEEL
        physics Physics {
        }
        linearVelocity 8.515928591235742e-07 1.2171057924967243e-08 6.805669258387879e-06
        angularVelocity -4.4629644032327295e-07 3.4063739850232405e-05 -4.4767751549574567e-10
      }
    }
    HingeJoint {
      jointParameters HingeJointParameters {
        position 1.8172959161559718e-07
        axis 0 1 0
        anchor 0 0 0.025
      }
      device [
        RotationalMotor {
          name "right wheel motor"
        }
      ]
      endPoint Solid {
        translation 0 -0.045 0.025
        rotation 0 1 0 1.812804499357409e-07
        children [
          USE WHEEL
        ]
        name "RIGHT WHEEL"
        boundingObject USE WHEEL
        physics Physics {
        }
        linearVelocity 8.515638589303115e-07 1.0188500770132001e-08 6.845982623344505e-06
        angularVelocity -4.480699151505333e-07 3.406375300197163e-05 -4.508579233068351e-10
      }
    }
    Transform {
      translation 0 0 0.045
      children [
        Shape {
          appearance PBRAppearance {
            baseColor 0 0 1
            roughness 1
            metalness 0
          }
          geometry DEF BODY Cylinder {
            height 0.08
            radius 0.045
          }
        }
      ]
    }
  ]
  name "qwerty"
  boundingObject Transform {
    translation 0 0 0.045
    children [
      USE BODY
    ]
  }
  physics Physics {
  }
  controller "<extern>"
  linearVelocity 1.4963983970642856e-06 2.012178137273894e-08 6.812063565712571e-06
  angularVelocity -4.4718325114402916e-07 3.224191644039442e-05 -4.6362763854826443e-10
}
